Workbook

Sheet NBA
B1: Fecha | C1: Jugada | D1: Cuota | E1: Beneficio Neto | F1: Yield | G1: $ | H1: Jugada | I1: Diario | J1: Semanal | K1: Mensual | L1: Unidades
B2: 45971 | C2: 2.6 | D2: 1.862 | E2: =(C2*D2)-C2 -> 2.2412 | F2: =SUM($E$2:E2)/SUM($C$2:C2) -> 0.862 | G2: =E2 -> 2.2412 | H2: Los Angeles Lakers
C3: 2.6 | D3: 1.9 | E3: =(C3*D3)-C3 -> 2.34 | F3: =SUM($E$2:E3)/SUM($C$2:C3) -> 0.881 | G3: =G2+E3 -> 4.5812 | H3: Washington Wizards
C4: 2.6 | D4: 1.9 | E4: =(C4*D4)-C4 -> 2.34 | F4: =SUM($E$2:E4)/SUM($C$2:C4) -> 0.88733333 | G4: =G3+E4 -> 6.9212 | H4: San Antonio Spurs
C5: 2.6 | E5: =(C5*D5)-C5 -> -2.6 | F5: =SUM($E$2:E5)/SUM($C$2:C5) -> 0.4155 | G5: =G4+E5 -> 4.3212 | H5: New Orleans Pelicans
C6: 2.6 | E6: =(C6*D6)-C6 -> -2.6 | F6: =SUM($E$2:E6)/SUM($C$2:C6) -> 0.1324 | G6: =G5+E6 -> 1.7212 | H6: Atlanta Hawks
C7: 2.6 | D7: 1.704 | E7: =(C7*D7)-C7 -> 1.8304 | F7: =SUM($E$2:E7)/SUM($C$2:C7) -> 0.22766667 | G7: =G6+E7 -> 3.5516 | H7: Charlotte Hornets
C8: 2.6 | D8: 1.798 | E8: =(C8*D8)-C8 -> 2.0748 | F8: =SUM($E$2:E8)/SUM($C$2:C8) -> 0.30914286 | G8: =G7+E8 -> 5.6264 | H8: Miami Heat
C9: 2.6 | E9: =(C9*D9)-C9 -> -2.6 | F9: =SUM($E$2:E9)/SUM($C$2:C9) -> 0.1455 | G9: =G8+E9 -> 3.0264 | H9: Dallas Mavericks
C10: 2.6 | E10: =(C10*D10)-C10 -> -2.6 | F10: =SUM($E$2:E10)/SUM($C$2:C10) -> 0.018222222 | G10: =G9+E10 -> 0.4264 | H10: LA Clippers
C11: 2.6 | D11: 1.606 | E11: =(C11*D11)-C11 -> 1.5756 | F11: =SUM($E$2:E11)/SUM($C$2:C11) -> 0.077 | G11: =G10+E11 -> 2.002 | H11: Los Angeles Lakers @ Charlotte Hornets
C12: 2.6 | D12: 1.606 | E12: =(C12*D12)-C12 -> 1.5756 | F12: =SUM($E$2:E12)/SUM($C$2:C12) -> 0.12509091 | G12: =G11+E12 -> 3.5776 | H12: Washington Wizards @ Detroit Pistons
C13: 2.6 | D13: 1.606 | E13: =(C13*D13)-C13 -> 1.5756 | F13: =SUM($E$2:E13)/SUM($C$2:C13) -> 0.16516667 | G13: =G12+E13 -> 5.1532 | H13: San Antonio Spurs @ Chicago Bulls
C14: 2.6 | D14: 1.606 | E14: =(C14*D14)-C14 -> 1.5756 | F14: =SUM($E$2:E14)/SUM($C$2:C14) -> 0.19907692 | G14: =G13+E14 -> 6.7288 | H14: Milwaukee Bucks @ Dallas Mavericks
C15: 2.6 | E15: =(C15*D15)-C15 -> -2.6 | F15: =SUM($E$2:E15)/SUM($C$2:C15) -> 0.11342857 | G15: =G14+E15 -> 4.1288 | H15: New Orleans Pelicans @ Phoenix Suns
C16: 2.6 | E16: =(C16*D16)-C16 -> -2.6 | F16: =SUM($E$2:E16)/SUM($C$2:C16) -> 0.0392 | G16: =G15+E16 -> 1.5288 | H16: Atlanta Hawks @ LA Clippers | I16: =SUM(E2:E16) -> 1.5288 | L16: =I16/C16 -> 0.588
B17: 45972 | C17: 3.9 | E17: =(C17*D17)-C17 -> -3.9 | F17: =SUM($E$2:E17)/SUM($C$2:C17) -> -0.055272727 | G17: =G16+E17 -> -2.3712 | H17: Toronto Raptors
C18: 3.9 | D18: 1.845 | E18: =(C18*D18)-C18 -> 3.2955 | F18: =SUM($E$2:E18)/SUM($C$2:C18) -> 0.01975 | G18: =G17+E18 -> 0.9243 | H18: Memphis Grizzlies
C19: 3.9 | E19: =(C19*D19)-C19 -> -3.9 | F19: =SUM($E$2:E19)/SUM($C$2:C19) -> -0.058692308 | G19: =G18+E19 -> -2.9757 | H19: Golden State Warriors
C20: 3.9 | E20: =(C20*D20)-C20 -> -3.9 | F20: =SUM($E$2:E20)/SUM($C$2:C20) -> -0.12592857 | G20: =G19+E20 -> -6.8757 | H20: Brooklyn Nets
C21: 3.9 | D21: 1.764 | E21: =(C21*D21)-C21 -> 2.9796 | F21: =SUM($E$2:E21)/SUM($C$2:C21) -> -0.0666 | G21: =G20+E21 -> -3.8961 | H21: New York Knicks
C22: 3.9 | D22: 1.9 | E22: =(C22*D22)-C22 -> 3.51 | F22: =SUM($E$2:E22)/SUM($C$2:C22) -> -0.0061875 | G22: =G21+E22 -> -0.3861 | H22: Oklahoma City Thunder
C23: 3.9 | E23: =(C23*D23)-C23 -> -3.9 | F23: =SUM($E$2:E23)/SUM($C$2:C23) -> -0.064647059 | G23: =G22+E23 -> -4.2861 | H23: Toronto Raptors @ Brooklyn Nets
C24: 3.9 | D24: 1.606 | E24: =(C24*D24)-C24 -> 2.3634 | F24: =SUM($E$2:E24)/SUM($C$2:C24) -> -0.027388889 | G24: =G23+E24 -> -1.9227 | H24: Memphis Grizzlies @ New York Knicks
C25: 3.9 | D25: 1.606 | E25: =(C25*D25)-C25 -> 2.3634 | F25: =SUM($E$2:E25)/SUM($C$2:C25) -> 0.0059473684 | G25: =G24+E25 -> 0.4407 | H25: Golden State Warriors @ Oklahoma City Thunder | I25: =SUM(E17:E25) -> -1.0881 | L25: =I25/C25 -> -0.279
B26: 45973 | C26: 1.95 | E26: =(C26*D26)-C26 -> -1.95 | F26: =SUM($E$2:E26)/SUM($C$2:C26) -> -0.019846154 | G26: =G25+E26 -> -1.5093 | H26: Milwaukee Bucks
C27: 1.95 | E27: =(C27*D27)-C27 -> -1.95 | F27: =SUM($E$2:E27)/SUM($C$2:C27) -> -0.04435 | G27: =G26+E27 -> -3.4593 | H27: Chicago Bulls
C28: 1.95 | D28: 1.774 | E28: =(C28*D28)-C28 -> 1.5093 | F28: =SUM($E$2:E28)/SUM($C$2:C28) -> -0.024390244 | G28: =G27+E28 -> -1.95 | H28: Washington Wizards
C29: 1.95 | D29: 1.784 | E29: =(C29*D29)-C29 -> 1.5288 | F29: =SUM($E$2:E29)/SUM($C$2:C29) -> -0.0051428571 | G29: =G28+E29 -> -0.4212 | H29: Phoenix Suns
C30: 1.95 | E30: =(C30*D30)-C30 -> -1.95 | F30: =SUM($E$2:E30)/SUM($C$2:C30) -> -0.02827907 | G30: =G29+E30 -> -2.3712 | H30: Charlotte Hornets
C31: 1.95 | D31: 1.939 | E31: =(C31*D31)-C31 -> 1.83105 | F31: =SUM($E$2:E31)/SUM($C$2:C31) -> -0.0062954545 | G31: =G30+E31 -> -0.54015 | H31: Boston Celtics
C32: 1.95 | D32: 1.65 | E32: =(C32*D32)-C32 -> 1.2675 | F32: =SUM($E$2:E32)/SUM($C$2:C32) -> 0.0082888889 | G32: =G31+E32 -> 0.72735 | H32: New Orleans Pelicans
C33: 1.95 | D33: 1.9 | E33: =(C33*D33)-C33 -> 1.755 | F33: =SUM($E$2:E33)/SUM($C$2:C33) -> 0.027673913 | G33: =G32+E33 -> 2.48235 | H33: Dallas Mavericks
C34: 1.95 | D34: 1.9 | E34: =(C34*D34)-C34 -> 1.755 | F34: =SUM($E$2:E34)/SUM($C$2:C34) -> 0.046234043 | G34: =G33+E34 -> 4.23735 | H34: Oklahoma City Thunder
C35: 1.95 | E35: =(C35*D35)-C35 -> -1.95 | F35: =SUM($E$2:E35)/SUM($C$2:C35) -> 0.0244375 | G35: =G34+E35 -> 2.28735 | H35: Sacramento Kings
C36: 1.95 | E36: =(C36*D36)-C36 -> -1.95 | F36: =SUM($E$2:E36)/SUM($C$2:C36) -> 0.0035306122 | G36: =G35+E36 -> 0.33735 | H36: Milwaukee Bucks @ Charlotte Hornets
C37: 1.95 | D37: 1.606 | E37: =(C37*D37)-C37 -> 1.1817 | F37: =SUM($E$2:E37)/SUM($C$2:C37) -> 0.01558 | G37: =G36+E37 -> 1.51905 | H37: Chicago Bulls @ Detroit Pistons
C38: 1.95 | D38: 1 | E38: =(C38*D38)-C38 -> 0 | F38: =SUM($E$2:E38)/SUM($C$2:C38) -> 0.01527451 | G38: =G37+E38 -> 1.51905 | H38: Memphis Grizzlies @ Boston Celtics
C39: 1.95 | D39: 1.606 | E39: =(C39*D39)-C39 -> 1.1817 | F39: =SUM($E$2:E39)/SUM($C$2:C39) -> 0.026634615 | G39: =G38+E39 -> 2.70075 | H39: Portland Trail Blazers @ New Orleans Pelicans
C40: 1.95 | D40: 1.606 | E40: =(C40*D40)-C40 -> 1.1817 | F40: =SUM($E$2:E40)/SUM($C$2:C40) -> 0.037566038 | G40: =G39+E40 -> 3.88245 | H40: Phoenix Suns @ Dallas Mavericks
...

Sheet Jornada
A1: Fecha | B1: Partido | C1: Visitante | D1: Pro | E1: Real | F1: OU_V | G1: Home | H1: Pro2 | I1: Real3 | J1: O/U_H | K1: Tot | L1: Tot R | M1: O/U_T | N1: Dif | O1: Real4 | P1: W/L | Q1: Semana | R1: Mes
A2: 45951 | B2: Houston Rockets @ Oklahoma City Thunder | C2: =LEFT(B2,FIND("@",B2)-2) -> Houston Rockets | D2: 101 | E2: 124 | F2: =IF(E2>D2, 1, 0) -> 1 | G2: =MID(B2,FIND("@",B2)+2,LEN(B2)-FIND("@",B2)-1) -> Oklahoma City Thunder | H2: 114 | I2: 125 | J2: =IF(I2>H2, 1, 0) -> 1 | K2: =+D2+H2 -> 215 | L2: =E2+I2 -> 249 | M2: =IF(L2>K2, 1, 0) -> 1 | N2: =(+H2-D2) -> 13 | O2: =I2-E2 -> 1 | P2: =IF(OR(AND(N2>0,O2>0),AND(N2<0,O2<0)),1,0) -> 1 | Q2: =WEEKNUM(tblResultadosNBA[[#This Row],[Fecha]],2) -> 43 | R2: =TEXT(tblResultadosNBA[[#This Row],[Fecha]],"mmm") -> oct
A3: 45951 | B3: Golden State Warriors @ Los Angeles Lakers | C3: =LEFT(B3,FIND("@",B3)-2) -> Golden State Warriors | D3: 99 | E3: 119 | F3: =IF(E3>D3, 1, 0) -> 1 | G3: =MID(B3,FIND("@",B3)+2,LEN(B3)-FIND("@",B3)-1) -> Los Angeles Lakers | H3: 119 | I3: 109 | J3: =IF(I3>H3, 1, 0) -> 0 | K3: =+D3+H3 -> 218 | L3: =E3+I3 -> 228 | M3: =IF(L3>K3, 1, 0) -> 1 | N3: =(+H3-D3) -> 20 | O3: =I3-E3 -> -10 | P3: =IF(OR(AND(N3>0,O3>0),AND(N3<0,O3<0)),1,0) -> 0 | Q3: =WEEKNUM(tblResultadosNBA[[#This Row],[Fecha]],2) -> 43 | R3: =TEXT(tblResultadosNBA[[#This Row],[Fecha]],"mmm") -> oct
A4: 45952 | B4: Cleveland Cavaliers @ New York Knicks | C4: =LEFT(B4,FIND("@",B4)-2) -> Cleveland Cavaliers | D4: 94 | E4: 111 | F4: =IF(E4>D4, 1, 0) -> 1 | G4: =MID(B4,FIND("@",B4)+2,LEN(B4)-FIND("@",B4)-1) -> New York Knicks | H4: 117 | I4: 119 | J4: =IF(I4>H4, 1, 0) -> 1 | K4: =+D4+H4 -> 211 | L4: =E4+I4 -> 230 | M4: =IF(L4>K4, 1, 0) -> 1 | N4: =(+H4-D4) -> 23 | O4: =I4-E4 -> 8 | P4: =IF(OR(AND(N4>0,O4>0),AND(N4<0,O4<0)),1,0) -> 1 | Q4: =WEEKNUM(tblResultadosNBA[[#This Row],[Fecha]],2) -> 43 | R4: =TEXT(tblResultadosNBA[[#This Row],[Fecha]],"mmm") -> oct
A5: 45952 | B5: Brooklyn Nets @ Charlotte Hornets | C5: =LEFT(B5,FIND("@",B5)-2) -> Brooklyn Nets | D5: 109 | E5: 117 | F5: =IF(E5>D5, 1, 0) -> 1 | G5: =MID(B5,FIND("@",B5)+2,LEN(B5)-FIND("@",B5)-1) -> Charlotte Hornets | H5: 117 | I5: 136 | J5: =IF(I5>H5, 1, 0) -> 1 | K5: =+D5+H5 -> 226 | L5: =E5+I5 -> 253 | M5: =IF(L5>K5, 1, 0) -> 1 | N5: =(+H5-D5) -> 8 | O5: =I5-E5 -> 19 | P5: =IF(OR(AND(N5>0,O5>0),AND(N5<0,O5<0)),1,0) -> 1 | Q5: =WEEKNUM(tblResultadosNBA[[#This Row],[Fecha]],2) -> 43 | R5: =TEXT(tblResultadosNBA[[#This Row],[Fecha]],"mmm") -> oct
A6: 45952 | B6: Miami Heat @ Orlando Magic | C6: =LEFT(B6,FIND("@",B6)-2) -> Miami Heat | D6: 108 | E6: 121 | F6: =IF(E6>D6, 1, 0) -> 1 | G6: =MID(B6,FIND("@",B6)+2,LEN(B6)-FIND("@",B6)-1) -> Orlando Magic | H6: 120 | I6: 125 | J6: =IF(I6>H6, 1, 0) -> 1 | K6: =+D6+H6 -> 228 | L6: =E6+I6 -> 246 | M6: =IF(L6>K6, 1, 0) -> 1 | N6: =(+H6-D6) -> 12 | O6: =I6-E6 -> 4 | P6: =IF(OR(AND(N6>0,O6>0),AND(N6<0,O6<0)),1,0) -> 1 | Q6: =WEEKNUM(tblResultadosNBA[[#This Row],[Fecha]],2) -> 43 | R6: =TEXT(tblResultadosNBA[[#This Row],[Fecha]],"mmm") -> oct
A7: 45952 | B7: Toronto Raptors @ Atlanta Hawks | C7: =LEFT(B7,FIND("@",B7)-2) -> Toronto Raptors | D7: 104 | E7: 138 | F7: =IF(E7>D7, 1, 0) -> 1 | G7: =MID(B7,FIND("@",B7)+2,LEN(B7)-FIND("@",B7)-1) -> Atlanta Hawks | H7: 119 | I7: 118 | J7: =IF(I7>H7, 1, 0) -> 0 | K7: =+D7+H7 -> 223 | L7: =E7+I7 -> 256 | M7: =IF(L7>K7, 1, 0) -> 1 | N7: =(+H7-D7) -> 15 | O7: =I7-E7 -> -20 | P7: =IF(OR(AND(N7>0,O7>0),AND(N7<0,O7<0)),1,0) -> 0 | Q7: =WEEKNUM(tblResultadosNBA[[#This Row],[Fecha]],2) -> 43 | R7: =TEXT(tblResultadosNBA[[#This Row],[Fecha]],"mmm") -> oct
A8: 45952 | B8: Philadelphia 76ers @ Boston Celtics | C8: =LEFT(B8,FIND("@",B8)-2) -> Philadelphia 76ers | D8: 107 | E8: 117 | F8: =IF(E8>D8, 1, 0) -> 1 | G8: =MID(B8,FIND("@",B8)+2,LEN(B8)-FIND("@",B8)-1) -> Boston Celtics | H8: 128 | I8: 116 | J8: =IF(I8>H8, 1, 0) -> 0 | K8: =+D8+H8 -> 235 | L8: =E8+I8 -> 233 | M8: =IF(L8>K8, 1, 0) -> 0 | N8: =(+H8-D8) -> 21 | O8: =I8-E8 -> -1 | P8: =IF(OR(AND(N8>0,O8>0),AND(N8<0,O8<0)),1,0) -> 0 | Q8: =WEEKNUM(tblResultadosNBA[[#This Row],[Fecha]],2) -> 43 | R8: =TEXT(tblResultadosNBA[[#This Row],[Fecha]],"mmm") -> oct
A9: 45952 | B9: Detroit Pistons @ Chicago Bulls | C9: =LEFT(B9,FIND("@",B9)-2) -> Detroit Pistons | D9: 99 | E9: 111 | F9: =IF(E9>D9, 1, 0) -> 1 | G9: =MID(B9,FIND("@",B9)+2,LEN(B9)-FIND("@",B9)-1) -> Chicago Bulls | H9: 116 | I9: 105 | J9: =IF(I9>H9, 1, 0) -> 0 | K9: =+D9+H9 -> 215 | L9: =E9+I9 -> 216 | M9: =IF(L9>K9, 1, 0) -> 1 | N9: =(+H9-D9) -> 17 | O9: =I9-E9 -> -6 | P9: =IF(OR(AND(N9>0,O9>0),AND(N9<0,O9<0)),1,0) -> 0 | Q9: =WEEKNUM(tblResultadosNBA[[#This Row],[Fecha]],2) -> 43 | R9: =TEXT(tblResultadosNBA[[#This Row],[Fecha]],"mmm") -> oct
A10: 45952 | B10: New Orleans Pelicans @ Memphis Grizzlies | C10: =LEFT(B10,FIND("@",B10)-2) -> New Orleans Pelicans | D10: 109 | E10: 122 | F10: =IF(E10>D10, 1, 0) -> 1 | G10: =MID(B10,FIND("@",B10)+2,LEN(B10)-FIND("@",B10)-1) -> Memphis Grizzlies | H10: 118 | I10: 128 | J10: =IF(I10>H10, 1, 0) -> 1 | K10: =+D10+H10 -> 227 | L10: =E10+I10 -> 250 | M10: =IF(L10>K10, 1, 0) -> 1 | N10: =(+H10-D10) -> 9 | O10: =I10-E10 -> 6 | P10: =IF(OR(AND(N10>0,O10>0),AND(N10<0,O10<0)),1,0) -> 1 | Q10: =WEEKNUM(tblResultadosNBA[[#This Row],[Fecha]],2) -> 43 | R10: =TEXT(tblResultadosNBA[[#This Row],[Fecha]],"mmm") -> oct
A11: 45952 | B11: Washington Wizards @ Milwaukee Bucks | C11: =LEFT(B11,FIND("@",B11)-2) -> Washington Wizards | D11: 109 | E11: 120 | F11: =IF(E11>D11, 1, 0) -> 1 | G11: =MID(B11,FIND("@",B11)+2,LEN(B11)-FIND("@",B11)-1) -> Milwaukee Bucks | H11: 114 | I11: 133 | J11: =IF(I11>H11, 1, 0) -> 1 | K11: =+D11+H11 -> 223 | L11: =E11+I11 -> 253 | M11: =IF(L11>K11, 1, 0) -> 1 | N11: =(+H11-D11) -> 5 | O11: =I11-E11 -> 13 | P11: =IF(OR(AND(N11>0,O11>0),AND(N11<0,O11<0)),1,0) -> 1 | Q11: =WEEKNUM(tblResultadosNBA[[#This Row],[Fecha]],2) -> 43 | R11: =TEXT(tblResultadosNBA[[#This Row],[Fecha]],"mmm") -> oct
A12: 45952 | B12: LA Clippers @ Utah Jazz | C12: =LEFT(B12,FIND("@",B12)-2) -> LA Clippers | D12: 115 | E12: 108 | F12: =IF(E12>D12, 1, 0) -> 0 | G12: =MID(B12,FIND("@",B12)+2,LEN(B12)-FIND("@",B12)-1) -> Utah Jazz | H12: 118 | I12: 129 | J12: =IF(I12>H12, 1, 0) -> 1 | K12: =+D12+H12 -> 233 | L12: =E12+I12 -> 237 | M12: =IF(L12>K12, 1, 0) -> 1 | N12: =(+H12-D12) -> 3 | O12: =I12-E12 -> 21 | P12: =IF(OR(AND(N12>0,O12>0),AND(N12<0,O12<0)),1,0) -> 1 | Q12: =WEEKNUM(tblResultadosNBA[[#This Row],[Fecha]],2) -> 43 | R12: =TEXT(tblResultadosNBA[[#This Row],[Fecha]],"mmm") -> oct
A13: 45952 | B13: San Antonio Spurs @ Dallas Mavericks | C13: =LEFT(B13,FIND("@",B13)-2) -> San Antonio Spurs | D13: 103 | E13: 125 | F13: =IF(E13>D13, 1, 0) -> 1 | G13: =MID(B13,FIND("@",B13)+2,LEN(B13)-FIND("@",B13)-1) -> Dallas Mavericks | H13: 114 | I13: 92 | J13: =IF(I13>H13, 1, 0) -> 0 | K13: =+D13+H13 -> 217 | L13: =E13+I13 -> 217 | M13: =IF(L13>K13, 1, 0) -> 0 | N13: =(+H13-D13) -> 11 | O13: =I13-E13 -> -33 | P13: =IF(OR(AND(N13>0,O13>0),AND(N13<0,O13<0)),1,0) -> 0 | Q13: =WEEKNUM(tblResultadosNBA[[#This Row],[Fecha]],2) -> 43 | R13: =TEXT(tblResultadosNBA[[#This Row],[Fecha]],"mmm") -> oct
... A299: 45991 | B299: Memphis Grizzlies @ Sacramento Kings | C299: =LEFT(B299,FIND("@",B299)-2) -> Memphis Grizzlies | D299: 120 | E299: 115 | F299: =IF(E299>D299, 1, 0) -> 0 | G299: =MID(B299,FIND("@",B299)+2,LEN(B299)-FIND("@",B299)-1) -> Sacramento Kings | H299: 113 | I299: 107 | J299: =IF(I299>H299, 1, 0) -> 0 | K299: =+D299+H299 -> 233 | L299: =E299+I299 -> 222 | M299: =IF(L299>K299, 1, 0) -> 0 | N299: =(+H299-D299) -> -7 | O299: =I299-E299 -> -8 | P299: =IF(OR(AND(N299>0,O299>0),AND(N299<0,O299<0)),1,0) -> 1 | Q299: =WEEKNUM(tblResultadosNBA[[#This Row],[Fecha]],2) -> 48 | R299: =TEXT(tblResultadosNBA[[#This Row],[Fecha]],"mmm") -> nov
A300: 45991 | B300: New Orleans Pelicans @ Los Angeles Lakers | C300: =LEFT(B300,FIND("@",B300)-2) -> New Orleans Pelicans | D300: 104 | E300: 121 | F300: =IF(E300>D300, 1, 0) -> 1 | G300: =MID(B300,FIND("@",B300)+2,LEN(B300)-FIND("@",B300)-1) -> Los Angeles Lakers | H300: 113 | I300: 133 | J300: =IF(I300>H300, 1, 0) -> 1 | K300: =+D300+H300 -> 217 | L300: =E300+I300 -> 254 | M300: =IF(L300>K300, 1, 0) -> 1 | N300: =(+H300-D300) -> 9 | O300: =I300-E300 -> 12 | P300: =IF(OR(AND(N300>0,O300>0),AND(N300<0,O300<0)),1,0) -> 1 | Q300: =WEEKNUM(tblResultadosNBA[[#This Row],[Fecha]],2) -> 48 | R300: =TEXT(tblResultadosNBA[[#This Row],[Fecha]],"mmm") -> nov | S300: ENTRENAMIENTO
A301: 45992 | B301: Atlanta Hawks @ Detroit Pistons | C301: =LEFT(B301,FIND("@",B301)-2) -> Atlanta Hawks | D301: 132 | E301: 98 | F301: =IF(E301>D301, 1, 0) -> 0 | G301: =MID(B301,FIND("@",B301)+2,LEN(B301)-FIND("@",B301)-1) -> Detroit Pistons | H301: 121 | I301: 99 | J301: =IF(I301>H301, 1, 0) -> 0 | K301: =+D301+H301 -> 253 | L301: =E301+I301 -> 197 | M301: =IF(L301>K301, 1, 0) -> 0 | N301: =(+H301-D301) -> -11 | O301: =I301-E301 -> 1 | P301: =IF(OR(AND(N301>0,O301>0),AND(N301<0,O301<0)),1,0) -> 0 | Q301: =WEEKNUM(tblResultadosNBA[[#This Row],[Fecha]],2) -> 49 | R301: =TEXT(tblResultadosNBA[[#This Row],[Fecha]],"mmm") -> dic
A302: 45992 | B302: Cleveland Cavaliers @ Indiana Pacers | C302: =LEFT(B302,FIND("@",B302)-2) -> Cleveland Cavaliers | D302: 120 | E302: 135 | F302: =IF(E302>D302, 1, 0) -> 1 | G302: =MID(B302,FIND("@",B302)+2,LEN(B302)-FIND("@",B302)-1) -> Indiana Pacers | H302: 116 | I302: 119 | J302: =IF(I302>H302, 1, 0) -> 1 | K302: =+D302+H302 -> 236 | L302: =E302+I302 -> 254 | M302: =IF(L302>K302, 1, 0) -> 1 | N302: =(+H302-D302) -> -4 | O302: =I302-E302 -> -16 | P302: =IF(OR(AND(N302>0,O302>0),AND(N302<0,O302<0)),1,0) -> 1 | Q302: =WEEKNUM(tblResultadosNBA[[#This Row],[Fecha]],2) -> 49 | R302: =TEXT(tblResultadosNBA[[#This Row],[Fecha]],"mmm") -> dic
A303: 45992 | B303: Milwaukee Bucks @ Washington Wizards | C303: =LEFT(B303,FIND("@",B303)-2) -> Milwaukee Bucks | D303: 116 | E303: 126 | F303: =IF(E303>D303, 1, 0) -> 1 | G303: =MID(B303,FIND("@",B303)+2,LEN(B303)-FIND("@",B303)-1) -> Washington Wizards | H303: 124 | I303: 129 | J303: =IF(I303>H303, 1, 0) -> 1 | K303: =+D303+H303 -> 240 | L303: =E303+I303 -> 255 | M303: =IF(L303>K303, 1, 0) -> 1 | N303: =(+H303-D303) -> 8 | O303: =I303-E303 -> 3 | P303: =IF(OR(AND(N303>0,O303>0),AND(N303<0,O303<0)),1,0) -> 1 | Q303: =WEEKNUM(tblResultadosNBA[[#This Row],[Fecha]],2) -> 49 | R303: =TEXT(tblResultadosNBA[[#This Row],[Fecha]],"mmm") -> dic
A304: 45992 | B304: Charlotte Hornets @ Brooklyn Nets | C304: =LEFT(B304,FIND("@",B304)-2) -> Charlotte Hornets | D304: 115 | E304: 103 | F304: =IF(E304>D304, 1, 0) -> 0 | G304: =MID(B304,FIND("@",B304)+2,LEN(B304)-FIND("@",B304)-1) -> Brooklyn Nets | H304: 113 | I304: 116 | J304: =IF(I304>H304, 1, 0) -> 1 | K304: =+D304+H304 -> 228 | L304: =E304+I304 -> 219 | M304: =IF(L304>K304, 1, 0) -> 0 | N304: =(+H304-D304) -> -2 | O304: =I304-E304 -> 13 | P304: =IF(OR(AND(N304>0,O304>0),AND(N304<0,O304<0)),1,0) -> 0 | Q304: =WEEKNUM(tblResultadosNBA[[#This Row],[Fecha]],2) -> 49 | R304: =TEXT(tblResultadosNBA[[#This Row],[Fecha]],"mmm") -> dic
A305: 45992 | B305: LA Clippers @ Miami Heat | C305: =LEFT(B305,FIND("@",B305)-2) -> LA Clippers | D305: 117 | E305: 123 | F305: =IF(E305>D305, 1, 0) -> 1 | G305: =MID(B305,FIND("@",B305)+2,LEN(B305)-FIND("@",B305)-1) -> Miami Heat | H305: 111 | I305: 140 | J305: =IF(I305>H305, 1, 0) -> 1 | K305: =+D305+H305 -> 228 | L305: =E305+I305 -> 263 | M305: =IF(L305>K305, 1, 0) -> 1 | N305: =(+H305-D305) -> -6 | O305: =I305-E305 -> 17 | P305: =IF(OR(AND(N305>0,O305>0),AND(N305<0,O305<0)),1,0) -> 0 | Q305: =WEEKNUM(tblResultadosNBA[[#This Row],[Fecha]],2) -> 49 | R305: =TEXT(tblResultadosNBA[[#This Row],[Fecha]],"mmm") -> dic
A306: 45992 | B306: Chicago Bulls @ Orlando Magic | C306: =LEFT(B306,FIND("@",B306)-2) -> Chicago Bulls | D306: 117 | E306: 120 | F306: =IF(E306>D306, 1, 0) -> 1 | G306: =MID(B306,FIND("@",B306)+2,LEN(B306)-FIND("@",B306)-1) -> Orlando Magic | H306: 122 | I306: 125 | J306: =IF(I306>H306, 1, 0) -> 1 | K306: =+D306+H306 -> 239 | L306: =E306+I306 -> 245 | M306: =IF(L306>K306, 1, 0) -> 1 | N306: =(+H306-D306) -> 5 | O306: =I306-E306 -> 5 | P306: =IF(OR(AND(N306>0,O306>0),AND(N306<0,O306<0)),1,0) -> 1 | Q306: =WEEKNUM(tblResultadosNBA[[#This Row],[Fecha]],2) -> 49 | R306: =TEXT(tblResultadosNBA[[#This Row],[Fecha]],"mmm") -> dic
A307: 45992 | B307: Dallas Mavericks @ Denver Nuggets | C307: =LEFT(B307,FIND("@",B307)-2) -> Dallas Mavericks | D307: 112 | E307: 131 | F307: =IF(E307>D307, 1, 0) -> 1 | G307: =MID(B307,FIND("@",B307)+2,LEN(B307)-FIND("@",B307)-1) -> Denver Nuggets | H307: 108 | I307: 121 | J307: =IF(I307>H307, 1, 0) -> 1 | K307: =+D307+H307 -> 220 | L307: =E307+I307 -> 252 | M307: =IF(L307>K307, 1, 0) -> 1 | N307: =(+H307-D307) -> -4 | O307: =I307-E307 -> -10 | P307: =IF(OR(AND(N307>0,O307>0),AND(N307<0,O307<0)),1,0) -> 1 | Q307: =WEEKNUM(tblResultadosNBA[[#This Row],[Fecha]],2) -> 49 | R307: =TEXT(tblResultadosNBA[[#This Row],[Fecha]],"mmm") -> dic
A308: 45992 | B308: Houston Rockets @ Utah Jazz | C308: =LEFT(B308,FIND("@",B308)-2) -> Houston Rockets | D308: 123 | E308: 125 | F308: =IF(E308>D308, 1, 0) -> 1 | G308: =MID(B308,FIND("@",B308)+2,LEN(B308)-FIND("@",B308)-1) -> Utah Jazz | H308: 124 | I308: 133 | J308: =IF(I308>H308, 1, 0) -> 1 | K308: =+D308+H308 -> 247 | L308: =E308+I308 -> 258 | M308: =IF(L308>K308, 1, 0) -> 1 | N308: =(+H308-D308) -> 1 | O308: =I308-E308 -> 8 | P308: =IF(OR(AND(N308>0,O308>0),AND(N308<0,O308<0)),1,0) -> 1 | Q308: =WEEKNUM(tblResultadosNBA[[#This Row],[Fecha]],2) -> 49 | R308: =TEXT(tblResultadosNBA[[#This Row],[Fecha]],"mmm") -> dic
A309: 45992 | B309: Phoenix Suns @ Los Angeles Lakers | C309: =LEFT(B309,FIND("@",B309)-2) -> Phoenix Suns | D309: 119 | E309: 125 | F309: =IF(E309>D309, 1, 0) -> 1 | G309: =MID(B309,FIND("@",B309)+2,LEN(B309)-FIND("@",B309)-1) -> Los Angeles Lakers | H309: 124 | I309: 108 | J309: =IF(I309>H309, 1, 0) -> 0 | K309: =+D309+H309 -> 243 | L309: =E309+I309 -> 233 | M309: =IF(L309>K309, 1, 0) -> 0 | N309: =(+H309-D309) -> 5 | O309: =I309-E309 -> -17 | P309: =IF(OR(AND(N309>0,O309>0),AND(N309<0,O309<0)),1,0) -> 0 | Q309: =WEEKNUM(tblResultadosNBA[[#This Row],[Fecha]],2) -> 49 | R309: =TEXT(tblResultadosNBA[[#This Row],[Fecha]],"mmm") -> dic
A310: 45993 | B310: Washington Wizards @ Philadelphia 76ers | C310: =LEFT(B310,FIND("@",B310)-2) -> Washington Wizards | D310: 126 | E310: 102 | F310: =IF(E310>D310, 1, 0) -> 0 | G310: =MID(B310,FIND("@",B310)+2,LEN(B310)-FIND("@",B310)-1) -> Philadelphia 76ers | H310: 130 | I310: 121 | J310: =IF(I310>H310, 1, 0) -> 0 | K310: =+D310+H310 -> 256 | L310: =E310+I310 -> 223 | M310: =IF(L310>K310, 1, 0) -> 0 | N310: =(+H310-D310) -> 4 | O310: =I310-E310 -> 19 | P310: =IF(OR(AND(N310>0,O310>0),AND(N310<0,O310<0)),1,0) -> 1 | Q310: =WEEKNUM(tblResultadosNBA[[#This Row],[Fecha]],2) -> 49 | R310: =TEXT(tblResultadosNBA[[#This Row],[Fecha]],"mmm") -> dic
A311: 45993 | B311: Portland Trail Blazers @ Toronto Raptors | C311: =LEFT(B311,FIND("@",B311)-2) -> Portland Trail Blazers | D311: 113 | E311: 118 | F311: =IF(E311>D311, 1, 0) -> 1 | G311: =MID(B311,FIND("@",B311)+2,LEN(B311)-FIND("@",B311)-1) -> Toronto Raptors | H311: 120 | I311: 121 | J311: =IF(I311>H311, 1, 0) -> 1 | K311: =+D311+H311 -> 233 | L311: =E311+I311 -> 239 | M311: =IF(L311>K311, 1, 0) -> 1 | N311: =(+H311-D311) -> 7 | O311: =I311-E311 -> 3 | P311: =IF(OR(AND(N311>0,O311>0),AND(N311<0,O311<0)),1,0) -> 1 | Q311: =WEEKNUM(tblResultadosNBA[[#This Row],[Fecha]],2) -> 49 | R311: =TEXT(tblResultadosNBA[[#This Row],[Fecha]],"mmm") -> dic
A312: 45993 | B312: New York Knicks @ Boston Celtics | C312: =LEFT(B312,FIND("@",B312)-2) -> New York Knicks | D312: 107 | E312: 117 | F312: =IF(E312>D312, 1, 0) -> 1 | G312: =MID(B312,FIND("@",B312)+2,LEN(B312)-FIND("@",B312)-1) -> Boston Celtics | H312: 126 | I312: 123 | J312: =IF(I312>H312, 1, 0) -> 0 | K312: =+D312+H312 -> 233 | L312: =E312+I312 -> 240 | M312: =IF(L312>K312, 1, 0) -> 1 | N312: =(+H312-D312) -> 19 | O312: =I312-E312 -> 6 | P312: =IF(OR(AND(N312>0,O312>0),AND(N312<0,O312<0)),1,0) -> 1 | Q312: =WEEKNUM(tblResultadosNBA[[#This Row],[Fecha]],2) -> 49 | R312: =TEXT(tblResultadosNBA[[#This Row],[Fecha]],"mmm") -> dic
... A485: 46020 | B485: Dallas Mavericks @ Portland Trail Blazers | C485: =LEFT(B485,FIND("@",B485)-2) -> Dallas Mavericks | D485: 119 | E485: 122 | F485: =IF(E485>D485, 1, 0) -> 1 | G485: =MID(B485,FIND("@",B485)+2,LEN(B485)-FIND("@",B485)-1) -> Portland Trail Blazers | H485: 123 | I485: 125 | J485: =IF(I485>H485, 1, 0) -> 1 | K485: =+D485+H485 -> 242 | L485: =E485+I485 -> 247 | M485: =IF(L485>K485, 1, 0) -> 1 | N485: =(+H485-D485) -> 4 | O485: =I485-E485 -> 3 | P485: =IF(OR(AND(N485>0,O485>0),AND(N485<0,O485<0)),1,0) -> 1 | Q485: =WEEKNUM(tblResultadosNBA[[#This Row],[Fecha]],2) -> 53 | R485: =TEXT(tblResultadosNBA[[#This Row],[Fecha]],"mmm") -> dic
A486: 46021 | B486: Philadelphia 76ers @ Memphis Grizzlies | C486: =LEFT(B486,FIND("@",B486)-2) -> Philadelphia 76ers | D486: 128 | E486: 139 | F486: =IF(E486>D486, 1, 0) -> 1 | G486: =MID(B486,FIND("@",B486)+2,LEN(B486)-FIND("@",B486)-1) -> Memphis Grizzlies | H486: 119 | I486: 136 | J486: =IF(I486>H486, 1, 0) -> 1 | K486: =+D486+H486 -> 247 | L486: =E486+I486 -> 275 | M486: =IF(L486>K486, 1, 0) -> 1 | N486: =(+H486-D486) -> -9 | O486: =I486-E486 -> -3 | P486: =IF(OR(AND(N486>0,O486>0),AND(N486<0,O486<0)),1,0) -> 1 | Q486: =WEEKNUM(tblResultadosNBA[[#This Row],[Fecha]],2) -> 53 | R486: =TEXT(tblResultadosNBA[[#This Row],[Fecha]],"mmm") -> dic | S486: =tblResultadosNBA[[#This Row],[Real]]-tblResultadosNBA[[#This Row],[Pro]] -> 11 | T486: =tblResultadosNBA[[#This Row],[Real3]]-tblResultadosNBA[[#This Row],[Pro2]] -> 17 | U486: =tblResultadosNBA[[#This Row],[Tot R]]-tblResultadosNBA[[#This Row],[Tot]] -> 28
A487: 46021 | B487: Boston Celtics @ Utah Jazz | C487: =LEFT(B487,FIND("@",B487)-2) -> Boston Celtics | D487: 122 | E487: 125 | F487: =IF(E487>D487, 1, 0) -> 1 | G487: =MID(B487,FIND("@",B487)+2,LEN(B487)-FIND("@",B487)-1) -> Utah Jazz | H487: 121 | I487: 119 | J487: =IF(I487>H487, 1, 0) -> 0 | K487: =+D487+H487 -> 243 | L487: =E487+I487 -> 244 | M487: =IF(L487>K487, 1, 0) -> 1 | N487: =(+H487-D487) -> -1 | O487: =I487-E487 -> -6 | P487: =IF(OR(AND(N487>0,O487>0),AND(N487<0,O487<0)),1,0) -> 1 | Q487: =WEEKNUM(tblResultadosNBA[[#This Row],[Fecha]],2) -> 53 | R487: =TEXT(tblResultadosNBA[[#This Row],[Fecha]],"mmm") -> dic
A488: 46021 | B488: Detroit Pistons @ Los Angeles Lakers | C488: =LEFT(B488,FIND("@",B488)-2) -> Detroit Pistons | D488: 107 | E488: 128 | F488: =IF(E488>D488, 1, 0) -> 1 | G488: =MID(B488,FIND("@",B488)+2,LEN(B488)-FIND("@",B488)-1) -> Los Angeles Lakers | H488: 119 | I488: 106 | J488: =IF(I488>H488, 1, 0) -> 0 | K488: =+D488+H488 -> 226 | L488: =E488+I488 -> 234 | M488: =IF(L488>K488, 1, 0) -> 1 | N488: =(+H488-D488) -> 12 | O488: =I488-E488 -> -22 | P488: =IF(OR(AND(N488>0,O488>0),AND(N488<0,O488<0)),1,0) -> 0 | Q488: =WEEKNUM(tblResultadosNBA[[#This Row],[Fecha]],2) -> 53 | R488: =TEXT(tblResultadosNBA[[#This Row],[Fecha]],"mmm") -> dic
A489: 46021 | B489: Sacramento Kings @ LA Clippers | C489: =LEFT(B489,FIND("@",B489)-2) -> Sacramento Kings | D489: 116 | E489: 90 | F489: =IF(E489>D489, 1, 0) -> 0 | G489: =MID(B489,FIND("@",B489)+2,LEN(B489)-FIND("@",B489)-1) -> LA Clippers | H489: 126 | I489: 131 | J489: =IF(I489>H489, 1, 0) -> 1 | K489: =+D489+H489 -> 242 | L489: =E489+I489 -> 221 | M489: =IF(L489>K489, 1, 0) -> 0 | N489: =(+H489-D489) -> 10 | O489: =I489-E489 -> 41 | P489: =IF(OR(AND(N489>0,O489>0),AND(N489<0,O489<0)),1,0) -> 1 | Q489: =WEEKNUM(tblResultadosNBA[[#This Row],[Fecha]],2) -> 53 | R489: =TEXT(tblResultadosNBA[[#This Row],[Fecha]],"mmm") -> dic
A490: 46022 | B490: Golden State Warriors @ Charlotte Hornets | C490: =LEFT(B490,FIND("@",B490)-2) -> Golden State Warriors | D490: 133 | E490: 132 | F490: =IF(E490>D490, 1, 0) -> 0 | G490: =MID(B490,FIND("@",B490)+2,LEN(B490)-FIND("@",B490)-1) -> Charlotte Hornets | H490: 126 | I490: 125 | J490: =IF(I490>H490, 1, 0) -> 0 | K490: =+D490+H490 -> 259 | L490: =E490+I490 -> 257 | M490: =IF(L490>K490, 1, 0) -> 0 | N490: =(+H490-D490) -> -7 | O490: =I490-E490 -> -7 | P490: =IF(OR(AND(N490>0,O490>0),AND(N490<0,O490<0)),1,0) -> 1 | Q490: =WEEKNUM(tblResultadosNBA[[#This Row],[Fecha]],2) -> 53 | R490: =TEXT(tblResultadosNBA[[#This Row],[Fecha]],"mmm") -> dic
A491: 46022 | B491: Minnesota Timberwolves @ Atlanta Hawks | C491: =LEFT(B491,FIND("@",B491)-2) -> Minnesota Timberwolves | D491: 122 | E491: 102 | F491: =IF(E491>D491, 1, 0) -> 0 | G491: =MID(B491,FIND("@",B491)+2,LEN(B491)-FIND("@",B491)-1) -> Atlanta Hawks | H491: 119 | I491: 126 | J491: =IF(I491>H491, 1, 0) -> 1 | K491: =+D491+H491 -> 241 | L491: =E491+I491 -> 228 | M491: =IF(L491>K491, 1, 0) -> 0 | N491: =(+H491-D491) -> -3 | O491: =I491-E491 -> 24 | P491: =IF(OR(AND(N491>0,O491>0),AND(N491<0,O491<0)),1,0) -> 0 | Q491: =WEEKNUM(tblResultadosNBA[[#This Row],[Fecha]],2) -> 53 | R491: =TEXT(tblResultadosNBA[[#This Row],[Fecha]],"mmm") -> dic
A492: 46022 | B492: Orlando Magic @ Indiana Pacers | C492: =LEFT(B492,FIND("@",B492)-2) -> Orlando Magic | D492: 106 | E492: 112 | F492: =IF(E492>D492, 1, 0) -> 1 | G492: =MID(B492,FIND("@",B492)+2,LEN(B492)-FIND("@",B492)-1) -> Indiana Pacers | H492: 111 | I492: 110 | J492: =IF(I492>H492, 1, 0) -> 0 | K492: =+D492+H492 -> 217 | L492: =E492+I492 -> 222 | M492: =IF(L492>K492, 1, 0) -> 1 | N492: =(+H492-D492) -> 5 | O492: =I492-E492 -> -2 | P492: =IF(OR(AND(N492>0,O492>0),AND(N492<0,O492<0)),1,0) -> 0 | Q492: =WEEKNUM(tblResultadosNBA[[#This Row],[Fecha]],2) -> 53 | R492: =TEXT(tblResultadosNBA[[#This Row],[Fecha]],"mmm") -> dic
A493: 46022 | B493: Phoenix Suns @ Cleveland Cavaliers | C493: =LEFT(B493,FIND("@",B493)-2) -> Phoenix Suns | D493: 118 | E493: 113 | F493: =IF(E493>D493, 1, 0) -> 0 | G493: =MID(B493,FIND("@",B493)+2,LEN(B493)-FIND("@",B493)-1) -> Cleveland Cavaliers | H493: 121 | I493: 129 | J493: =IF(I493>H493, 1, 0) -> 1 | K493: =+D493+H493 -> 239 | L493: =E493+I493 -> 242 | M493: =IF(L493>K493, 1, 0) -> 1 | N493: =(+H493-D493) -> 3 | O493: =I493-E493 -> 16 | P493: =IF(OR(AND(N493>0,O493>0),AND(N493<0,O493<0)),1,0) -> 1 | Q493: =WEEKNUM(tblResultadosNBA[[#This Row],[Fecha]],2) -> 53 | R493: =TEXT(tblResultadosNBA[[#This Row],[Fecha]],"mmm") -> dic
A494: 46022 | B494: New Orleans Pelicans @ Chicago Bulls | C494: =LEFT(B494,FIND("@",B494)-2) -> New Orleans Pelicans | D494: 121 | E494: 118 | F494: =IF(E494>D494, 1, 0) -> 0 | G494: =MID(B494,FIND("@",B494)+2,LEN(B494)-FIND("@",B494)-1) -> Chicago Bulls | H494: 115 | I494: 134 | J494: =IF(I494>H494, 1, 0) -> 1 | K494: =+D494+H494 -> 236 | L494: =E494+I494 -> 252 | M494: =IF(L494>K494, 1, 0) -> 1 | N494: =(+H494-D494) -> -6 | O494: =I494-E494 -> 16 | P494: =IF(OR(AND(N494>0,O494>0),AND(N494<0,O494<0)),1,0) -> 0 | Q494: =WEEKNUM(tblResultadosNBA[[#This Row],[Fecha]],2) -> 53 | R494: =TEXT(tblResultadosNBA[[#This Row],[Fecha]],"mmm") -> dic
A495: 46022 | B495: New York Knicks @ San Antonio Spurs | C495: =LEFT(B495,FIND("@",B495)-2) -> New York Knicks | D495: 125 | E495: 132 | F495: =IF(E495>D495, 1, 0) -> 1 | G495: =MID(B495,FIND("@",B495)+2,LEN(B495)-FIND("@",B495)-1) -> San Antonio Spurs | H495: 133 | I495: 134 | J495: =IF(I495>H495, 1, 0) -> 1 | K495: =+D495+H495 -> 258 | L495: =E495+I495 -> 266 | M495: =IF(L495>K495, 1, 0) -> 1 | N495: =(+H495-D495) -> 8 | O495: =I495-E495 -> 2 | P495: =IF(OR(AND(N495>0,O495>0),AND(N495<0,O495<0)),1,0) -> 1 | Q495: =WEEKNUM(tblResultadosNBA[[#This Row],[Fecha]],2) -> 53 | R495: =TEXT(tblResultadosNBA[[#This Row],[Fecha]],"mmm") -> dic
A496: 46022 | B496: Denver Nuggets @ Toronto Raptors | C496: =LEFT(B496,FIND("@",B496)-2) -> Denver Nuggets | D496: 116 | E496: 106 | F496: =IF(E496>D496, 1, 0) -> 0 | G496: =MID(B496,FIND("@",B496)+2,LEN(B496)-FIND("@",B496)-1) -> Toronto Raptors | H496: 107 | I496: 103 | J496: =IF(I496>H496, 1, 0) -> 0 | K496: =+D496+H496 -> 223 | L496: =E496+I496 -> 209 | M496: =IF(L496>K496, 1, 0) -> 0 | N496: =(+H496-D496) -> -9 | O496: =I496-E496 -> -3 | P496: =IF(OR(AND(N496>0,O496>0),AND(N496<0,O496<0)),1,0) -> 1 | Q496: =WEEKNUM(tblResultadosNBA[[#This Row],[Fecha]],2) -> 53 | R496: =TEXT(tblResultadosNBA[[#This Row],[Fecha]],"mmm") -> dic
A497: 46022 | B497: Washington Wizards @ Milwaukee Bucks | C497: =LEFT(B497,FIND("@",B497)-2) -> Washington Wizards | D497: 108 | E497: 114 | F497: =IF(E497>D497, 1, 0) -> 1 | G497: =MID(B497,FIND("@",B497)+2,LEN(B497)-FIND("@",B497)-1) -> Milwaukee Bucks | H497: 125 | I497: 113 | J497: =IF(I497>H497, 1, 0) -> 0 | K497: =+D497+H497 -> 233 | L497: =E497+I497 -> 227 | M497: =IF(L497>K497, 1, 0) -> 0 | N497: =(+H497-D497) -> 17 | O497: =I497-E497 -> -1 | P497: =IF(OR(AND(N497>0,O497>0),AND(N497<0,O497<0)),1,0) -> 0 | Q497: =WEEKNUM(tblResultadosNBA[[#This Row],[Fecha]],2) -> 53 | R497: =TEXT(tblResultadosNBA[[#This Row],[Fecha]],"mmm") -> dic
...

Sheet Dashboard
A1: Dashboard NBA – Tendencias por Periodo
A2: Fecha de actualización | B2: =TODAY()-1 -> 46172
A4: Selecciona semana: | B4: Semana 32 | C4: =_xlfn.XLOOKUP(B4,Referencia!B2:B60,Referencia!A2:A60) -> 22
A6: Total de partidos | B6: =COUNTIFS(Jornada!Q2:Q1318, C4, Jornada!E2:E1318, "<>") -> 4
A7: Over Visitantes | B7: =COUNTIFS(Jornada!Q2:Q1318,C4,Jornada!F2:F1318,1) -> 2 | C7: =COUNTIFS(Jornada!Q2:Q1318,C4,Jornada!F2:F1318,1) / COUNTIFS(Jornada!Q2:Q1318, C4, Jornada!E2:E1318, "<>") -> 0.5 | D7: =1-C7 -> 0.5
A8: Over Local | B8: =COUNTIFS(Jornada!Q2:Q1318,C4,Jornada!J2:J1318,1) -> 2 | C8: =COUNTIFS(Jornada!Q2:Q1318,C4,Jornada!J2:J1318,1) / COUNTIFS(Jornada!Q2:Q1318, C4, Jornada!E2:E1318, "<>") -> 0.5 | D8: =1-C8 -> 0.5
A9: Over Total | B9: =COUNTIFS(Jornada!Q2:Q1318,C4,Jornada!M2:M1318,1) -> 1 | C9: =COUNTIFS(Jornada!Q2:Q1318,C4,Jornada!M2:M1318,1) / COUNTIFS(Jornada!Q2:Q1318, C4, Jornada!E2:E1318, "<>") -> 0.25 | D9: =1-C9 -> 0.75
A10: Pronostico partido | B10: =COUNTIFS(Jornada!Q2:Q1318,C4,Jornada!P2:P1318,1) -> 2 | C10: =COUNTIFS(Jornada!Q2:Q1318,C4,Jornada!P2:P1318,1) / COUNTIFS(Jornada!Q2:Q1318, C4, Jornada!E2:E1318, "<>") -> 0.5 | D10: =1-C10 -> 0.5
A12: Selecciona mes: | B12: may
A14: Total de partidos | B14: =COUNTIFS(Jornada!R2:R1318,B12, Jornada!E2:E1318, "<>") -> 38
A15: Over Visitantes | B15: =COUNTIFS(Jornada!R2:R1318,B12,Jornada!F2:F1318,1) -> 12 | C15: =B15/$B$14 -> 0.31578947 | D15: =1-C15 -> 0.68421053
A16: Over Local | B16: =COUNTIFS(Jornada!R2:R1318,B12,Jornada!J2:J1318,1) -> 13 | C16: =B16/$B$14 -> 0.34210526 | D16: =1-C16 -> 0.65789474
A17: Over Total | B17: =COUNTIFS(Jornada!R2:R1318,B12,Jornada!M2:M1318,1) -> 10 | C17: =B17/$B$14 -> 0.26315789 | D17: =1-C17 -> 0.73684211
A18: Pronostico partido | B18: =COUNTIFS(Jornada!R2:R1318,B12,Jornada!P2:P1318,1) -> 20 | C18: =B18/$B$14 -> 0.52631579 | D18: =1-C18 -> 0.47368421

Sheet T Dinamica
A1: Fecha | B1: Suma de OU_V | C1: Promedio de OU_V2 | D1: Suma de O/U_H | E1: Promedio de O/U_H2 | F1: Suma de O/U_T | G1: Promedio de O/U_T2 | H1: Suma de W/L | I1: Promedio de W/L2
A2: 45951 | B2: 2 | C2: 1 | D2: 1 | E2: 0.5 | F2: 2 | G2: 1 | H2: 1 | I2: 0.5
A3: 45952 | B3: 11 | C3: 0.91666667 | D3: 7 | E3: 0.58333333 | F3: 10 | G3: 0.83333333 | H3: 7 | I3: 0.58333333
A4: 45953 | B4: 2 | C4: 1 | D4: 2 | E4: 1 | F4: 2 | G4: 1 | H4: 2 | I4: 1
A5: 45954 | B5: 8 | C5: 0.66666667 | D5: 8 | E5: 0.66666667 | F5: 8 | G5: 0.66666667 | H5: 6 | I5: 0.5
A6: 45955 | B6: 3 | C6: 0.6 | D6: 3 | E6: 0.6 | F6: 3 | G6: 0.6 | H6: 2 | I6: 0.4
A7: 45956 | B7: 5 | C7: 0.55555556 | D7: 9 | E7: 1 | F7: 7 | G7: 0.77777778 | H7: 2 | I7: 0.22222222
A8: 45957 | B8: 7 | C8: 0.63636364 | D8: 6 | E8: 0.54545455 | F8: 7 | G8: 0.63636364 | H8: 5 | I8: 0.45454545
A9: 45958 | B9: 2 | C9: 0.4 | D9: 3 | E9: 0.6 | F9: 3 | G9: 0.6 | H9: 3 | I9: 0.6
A10: 45959 | B10: 4 | C10: 0.4 | D10: 7 | E10: 0.7 | F10: 4 | G10: 0.4 | H10: 3 | I10: 0.3
A11: 45960 | B11: 2 | C11: 0.5 | D11: 3 | E11: 0.75 | F11: 2 | G11: 0.5 | H11: 3 | I11: 0.75
A12: 45961 | B12: 5 | C12: 0.625 | D12: 3 | E12: 0.375 | F12: 3 | G12: 0.375 | H12: 2 | I12: 0.25
A13: 45962 | B13: 5 | C13: 0.83333333 | D13: 2 | E13: 0.33333333 | F13: 3 | G13: 0.5 | H13: 2 | I13: 0.33333333
... A208: 46172 | B208: 0 | C208: 0 | D208: 0 | E208: 0 | F208: 0 | G208: 0 | H208: 0 | I208: 0
A209: Total general | B209: 631 | C209: 0.47911921 | D209: 596 | E209: 0.45254366 | F209: 606 | G209: 0.46013667 | H209: 744 | I209: 0.56492027

Sheet Referencia
A1: Semana Año | B1: Semana Temporada | C1: Mes
A2: 43 | B2: Semana 1 | C2: =TEXT(tblResultadosNBA[[#This Row],[Fecha]],"mmm") -> oct
A3: 44 | B3: Semana 2 | C3: nov
A4: 45 | B4: Semana 3 | C4: dic
A5: 46 | B5: Semana 4 | C5: ene
A6: 47 | B6: Semana 5 | C6: feb
A7: 48 | B7: Semana 6 | C7: mar
A8: 49 | B8: Semana 7 | C8: abr
A9: 50 | B9: Semana 8 | C9: may
A10: 51 | B10: Semana 9 | C10: jun
A11: 52 | B11: Semana 10 | C11: jul
A12: 1 | B12: Semana 11 | C12: ago
A13: 2 | B13: Semana 12 | C13: sep
A14: 3 | B14: Semana 13
A15: 4 | B15: Semana 14
A16: 5 | B16: Semana 15
A17: 6 | B17: Semana 16
A18: 7 | B18: Semana 17
A19: 8 | B19: Semana 18
A20: 9 | B20: Semana 19
A21: 10 | B21: Semana 20
A22: 11 | B22: Semana 21
A23: 12 | B23: Semana 22
A24: 13 | B24: Semana 23
A25: 14 | B25: Semana 24
... A53: 42 | B53: Semana 52

Sheet MLB ML Over
A1: Fecha | B1: Jugada | C1: Cuota | D1: Beneficio Neto | E1: Yield | F1: $ | G1: Jugada | H1: Diario | I1: Semanal | J1: Mensual | M1: K% = W - [ (1 - W) / R ]
A2: 45905 | B2: 1 | C2: 3.04 | D2: =(B2*C2)-B2 -> 2.04 | E2: =SUM($D$2:D2)/SUM($B$2:B2) -> 2.04 | F2: =D2 -> 2.04 | G2: Milwaukee Brewers Over Individual
B3: 1 | C3: 1.93 | D3: =(B3*C3)-B3 -> 0.93 | E3: =SUM($D$2:D3)/SUM($B$2:B3) -> 1.485 | F3: =F2+D3 -> 2.97 | G3: Pittsburgh Pirates vs Milwaukee Brewers Over
B4: 1 | C4: 1.86 | D4: =(B4*C4)-B4 -> 0.86 | E4: =SUM($D$2:D4)/SUM($B$2:B4) -> 1.2766667 | F4: =F3+D4 -> 3.83 | G4: New York Yankees vs Toronto Blue Jays Over
B5: 1 | C5: 2.01 | D5: =(B5*C5)-B5 -> 1.01 | E5: =SUM($D$2:D5)/SUM($B$2:B5) -> 1.21 | F5: =F4+D5 -> 4.84 | G5: Atlanta Braves vs Seattle Mariners Over
B6: 1 | D6: =(B6*C6)-B6 -> -1 | E6: =SUM($D$2:D6)/SUM($B$2:B6) -> 0.768 | F6: =F5+D6 -> 3.84 | G6: Texas Rangers vs Houston Astros Over
A7: 45906 | B7: 1 | D7: =(B7*C7)-B7 -> -1 | E7: =SUM($D$2:D7)/SUM($B$2:B7) -> 0.47333333 | F7: =F6+D7 -> 2.84 | G7: San Francisco Giants Over Individual
B8: 1 | D8: =(B8*C8)-B8 -> -1 | E8: =SUM($D$2:D8)/SUM($B$2:B8) -> 0.26285714 | F8: =F7+D8 -> 1.84 | G8: New York Yankees vs Toronto Blue Jays Over
B9: 1 | D9: =(B9*C9)-B9 -> -1 | E9: =SUM($D$2:D9)/SUM($B$2:B9) -> 0.105 | F9: =F8+D9 -> 0.84 | G9: St. Louis Cardinals vs San Francisco Giants Over
B10: 1 | D10: =(B10*C10)-B10 -> -1 | E10: =SUM($D$2:D10)/SUM($B$2:B10) -> -0.017777778 | F10: =F9+D10 -> -0.16 | G10: Colorado Rockies vs San Diego Padres Over
B11: 1 | D11: =(B11*C11)-B11 -> -1 | E11: =SUM($D$2:D11)/SUM($B$2:B11) -> -0.116 | F11: =F10+D11 -> -1.16 | G11: Pittsburgh Pirates vs Milwaukee Brewers Over
B12: 1 | D12: =(B12*C12)-B12 -> -1 | E12: =SUM($D$2:D12)/SUM($B$2:B12) -> -0.19636364 | F12: =F11+D12 -> -2.16 | G12: Arizona Diamondbacks vs Boston Red Sox Over
B13: 1 | C13: 1.97 | D13: =(B13*C13)-B13 -> 0.97 | E13: =SUM($D$2:D13)/SUM($B$2:B13) -> -0.099166667 | F13: =F12+D13 -> -1.19 | G13: Kansas City Royals vs Minnesota Twins Over
A14: 45907 | B14: 1 | D14: =(B14*C14)-B14 -> -1 | E14: =SUM($D$2:D14)/SUM($B$2:B14) -> -0.16846154 | F14: =F13+D14 -> -2.19 | G14: Tampa Bay Rays Over Individual
B15: 1 | D15: =(B15*C15)-B15 -> -1 | E15: =SUM($D$2:D15)/SUM($B$2:B15) -> -0.22785714 | F15: =F14+D15 -> -3.19 | G15: Tampa Bay Rays vs Cleveland Guardians Over
B16: 1 | D16: =(B16*C16)-B16 -> -1 | E16: =SUM($D$2:D16)/SUM($B$2:B16) -> -0.27933333 | F16: =F15+D16 -> -4.19 | G16: St. Louis Cardinals vs San Francisco Giants Over
B17: 1 | C17: 1.9 | D17: =(B17*C17)-B17 -> 0.9 | E17: =SUM($D$2:D17)/SUM($B$2:B17) -> -0.205625 | F17: =F16+D17 -> -3.29 | G17: New York Yankees vs Toronto Blue Jays Over
B18: 1 | C18: 1.88 | D18: =(B18*C18)-B18 -> 0.88 | E18: =SUM($D$2:D18)/SUM($B$2:B18) -> -0.14176471 | F18: =F17+D18 -> -2.41 | G18: Miami Marlins vs Philadelphia Phillies Over
B19: 1 | D19: =(B19*C19)-B19 -> -1 | E19: =SUM($D$2:D19)/SUM($B$2:B19) -> -0.18944444 | F19: =F18+D19 -> -3.41 | G19: Arizona Diamondbacks vs Boston Red Sox Over
A20: 45908 | B20: 1 | D20: =(B20*C20)-B20 -> -1 | E20: =SUM($D$2:D20)/SUM($B$2:B20) -> -0.23210526 | F20: =F19+D20 -> -4.41 | G20: San Francisco Giants vs Arizona Diamondbacks Over
B21: 1 | D21: =(B21*C21)-B21 -> -1 | E21: =SUM($D$2:D21)/SUM($B$2:B21) -> -0.2705 | F21: =F20+D21 -> -5.41 | G21: Philadelphia Phillies vs New York Mets Over
B22: 1 | C22: 1.909 | D22: =(B22*C22)-B22 -> 0.909 | E22: =SUM($D$2:D22)/SUM($B$2:B22) -> -0.21433333 | F22: =F21+D22 -> -4.501 | G22: Atlanta Braves vs Chicago Cubs Over
B23: 1 | D23: =(B23*C23)-B23 -> -1 | E23: =SUM($D$2:D23)/SUM($B$2:B23) -> -0.25004545 | F23: =F22+D23 -> -5.501 | G23: Texas Rangers vs Milwaukee Brewers Over
A24: 45909 | B24: 1 | C24: 1.74 | D24: =(B24*C24)-B24 -> 0.74 | E24: =SUM($D$2:D24)/SUM($B$2:B24) -> -0.207 | F24: =F23+D24 -> -4.761 | G24: Athletics vs Boston Red Sox Over
B25: 1 | C25: 1.89 | D25: =(B25*C25)-B25 -> 0.89 | E25: =SUM($D$2:D25)/SUM($B$2:B25) -> -0.16129167 | F25: =F24+D25 -> -3.871 | G25: Los Angeles Angels vs Minnesota Twins Over
B26: 1 | D26: =(B26*C26)-B26 -> -1 | E26: =SUM($D$2:D26)/SUM($B$2:B26) -> -0.19484 | F26: =F25+D26 -> -4.871 | G26: Texas Rangers vs Milwaukee Brewers Over
A27: 45910 | B27: 1 | C27: 2.85 | D27: =(B27*C27)-B27 -> 1.85 | E27: =SUM($D$2:D27)/SUM($B$2:B27) -> -0.11619231 | F27: =F26+D27 -> -3.021 | G27: Athletics Over Individual
B28: 1 | C28: 1.727 | D28: =(B28*C28)-B28 -> 0.727 | E28: =SUM($D$2:D28)/SUM($B$2:B28) -> -0.084962963 | F28: =F27+D28 -> -2.294 | G28: Athletics vs Boston Red Sox Over
B29: 1 | D29: =(B29*C29)-B29 -> -1 | E29: =SUM($D$2:D29)/SUM($B$2:B29) -> -0.11764286 | F29: =F28+D29 -> -3.294 | G29: Atlanta Braves vs Chicago Cubs Over
B30: 1 | D30: =(B30*C30)-B30 -> -1 | E30: =SUM($D$2:D30)/SUM($B$2:B30) -> -0.14806897 | F30: =F29+D30 -> -4.294 | G30: Los Angeles Angels vs Minnesota Twins Over
A31: 45911 | B31: 1 | C31: 2.99 | D31: =(B31*C31)-B31 -> 1.99 | E31: =SUM($D$2:D31)/SUM($B$2:B31) -> -0.0768 | F31: =F30+D31 -> -2.304 | G31: Toronto Blue Jays Over Individual
B32: 1 | C32: 1.92 | D32: =(B32*C32)-B32 -> 0.92 | E32: =SUM($D$2:D32)/SUM($B$2:B32) -> -0.044645161 | F32: =F31+D32 -> -1.384 | G32: Toronto Blue Jays vs Houston Astros Over
B33: 1 | C33: 1.98 | D33: =(B33*C33)-B33 -> 0.98 | E33: =SUM($D$2:D33)/SUM($B$2:B33) -> -0.012625 | F33: =F32+D33 -> -0.404 | G33: Miami Marlins vs Washington Nationals Over
A34: 45912 | B34: 1 | C34: 1.76 | D34: =(B34*C34)-B34 -> 0.76 | E34: =SUM($D$2:D34)/SUM($B$2:B34) -> 0.010787879 | F34: =F33+D34 -> 0.356 | G34: Athletics vs Cincinnati Reds Over
B35: 1 | D35: =(B35*C35)-B35 -> -1 | E35: =SUM($D$2:D35)/SUM($B$2:B35) -> -0.018941176 | F35: =F34+D35 -> -0.644 | G35: Atlanta Braves vs Houston Astros Over
B36: 1 | C36: 1.93 | D36: =(B36*C36)-B36 -> 0.93 | E36: =SUM($D$2:D36)/SUM($B$2:B36) -> 0.0081714286 | F36: =F35+D36 -> 0.286 | G36: Minnesota Twins vs Arizona Diamondbacks Over
B37: 1 | D37: =(B37*C37)-B37 -> -1 | E37: =SUM($D$2:D37)/SUM($B$2:B37) -> -0.019833333 | F37: =F36+D37 -> -0.714 | G37: Cleveland Guardians vs Chicago White Sox Over
B38: 1 | C38: 1.89 | D38: =(B38*C38)-B38 -> 0.89 | E38: =SUM($D$2:D38)/SUM($B$2:B38) -> 0.0047567568 | F38: =F37+D38 -> 0.176 | G38: Boston Red Sox vs New York Yankees Over
A39: 45913 | B39: 1 | C39: 1.89 | D39: =(B39*C39)-B39 -> 0.89 | E39: =SUM($D$2:D39)/SUM($B$2:B39) -> 0.028052632 | F39: =F38+D39 -> 1.066 | G39: Toronto Blue Jays vs Baltimore Orioles Over
B40: 1 | C40: 2.02 | D40: =(B40*C40)-B40 -> 1.02 | E40: =SUM($D$2:D40)/SUM($B$2:B40) -> 0.053487179 | F40: =F39+D40 -> 2.086 | G40: San Francisco Giants vs Los Angeles Dodgers Over
...

Sheet MLB ML Over Individual
A1: Fecha | B1: Jugada | C1: Cuota | D1: Beneficio Neto | E1: Yield | F1: $ | G1: Jugada | H1: Diario | I1: Semanal | J1: Mensual | O1: Kelly | P1: Stake | Q1: $ | T1: K% = W - [ (1 - W) / R ]
A2: 45905 | B2: 1 | C2: 3.04 | D2: =(B2*C2)-B2 -> 2.04 | E2: =SUM($D$2:D2)/SUM($B$2:B2) -> 2.04 | F2: =D2 -> 2.04 | G2: Milwaukee Brewers Over Individual | K2: 0.554 | L2: =K2 -> 0.554 | M2: =1/L2 -> 1.8050542 | N2: =IF(C2>=M2,1,0) -> 1 | O2: =L2-((1-L2)/D2) -> 0.33537255 | P2: =O2/10 -> 0.033537255 | Q2: =$O$21*P2 -> 2.4867204
A3: 45906 | B3: 1 | D3: =(B3*C3)-B3 -> -1 | E3: =SUM($D$2:D3)/SUM($B$2:B3) -> 0.52 | F3: =F2+D3 -> 1.04 | G3: San Francisco Giants Over Individual | K3: 0.5 | L3: =K3 -> 0.5 | M3: =1/L3 -> 2 | N3: =IF(C3>=M3,1,0) -> 0 | O3: =L3-((1-L3)/D3) -> 1 | P3: =O3/10 -> 0.1 | Q3: =$O$21*P3 -> 7.4148
A4: 45907 | B4: 1 | D4: =(B4*C4)-B4 -> -1 | E4: =SUM($D$2:D4)/SUM($B$2:B4) -> 0.013333333 | F4: =F3+D4 -> 0.04 | G4: Tampa Bay Rays Over Individual | K4: 0.617 | L4: =K4 -> 0.617 | M4: =1/L4 -> 1.6207455 | N4: =IF(C4>=M4,1,0) -> 0 | O4: =L4-((1-L4)/D4) -> 1 | P4: =O4/10 -> 0.1 | Q4: =$O$21*P4 -> 7.4148
A5: 45910 | B5: 1 | C5: 2.85 | D5: =(B5*C5)-B5 -> 1.85 | E5: =SUM($D$2:D5)/SUM($B$2:B5) -> 0.4725 | F5: =F4+D5 -> 1.89 | G5: Athletics Over Individual | K5: 0.548 | L5: =K5 -> 0.548 | M5: =1/L5 -> 1.8248175 | N5: =IF(C5>=M5,1,0) -> 1 | O5: =L5-((1-L5)/D5) -> 0.30367568 | P5: =O5/10 -> 0.030367568 | Q5: =$O$21*P5 -> 2.2516944
A6: 45911 | B6: 1 | C6: 2.99 | D6: =(B6*C6)-B6 -> 1.99 | E6: =SUM($D$2:D6)/SUM($B$2:B6) -> 0.776 | F6: =F5+D6 -> 3.88 | G6: Toronto Blue Jays Over Individual | K6: 0.556 | L6: =K6 -> 0.556 | M6: =1/L6 -> 1.7985612 | N6: =IF(C6>=M6,1,0) -> 1 | O6: =L6-((1-L6)/D6) -> 0.33288442 | P6: =O6/10 -> 0.033288442 | Q6: =$O$21*P6 -> 2.4682714
A7: 45917 | B7: 1 | C7: 3.14 | D7: =(B7*C7)-B7 -> 2.14 | E7: =SUM($D$2:D7)/SUM($B$2:B7) -> 1.0033333 | F7: =F6+D7 -> 6.02 | G7: Chicago Cubs Over Individual
B8: 1 | C8: 2.81 | D8: =(B8*C8)-B8 -> 1.81 | E8: =SUM($D$2:D8)/SUM($B$2:B8) -> 1.1185714 | F8: =F7+D8 -> 7.83 | G8: Boston Red Sox Over Individual
A9: 45921 | B9: 1 | D9: =(B9*C9)-B9 -> -1 | E9: =SUM($D$2:D9)/SUM($B$2:B9) -> 0.85375 | F9: =F8+D9 -> 6.83 | G9: Kansas City Royals Over Individual
B10: 1 | D10: =(B10*C10)-B10 -> -1 | E10: =SUM($D$2:D10)/SUM($B$2:B10) -> 0.64777778 | F10: =F9+D10 -> 5.83 | G10: New York Yankees Over Individual
A11: 45922 | B11: 1 | C11: 2.81 | D11: =(B11*C11)-B11 -> 1.81 | E11: =SUM($D$2:D11)/SUM($B$2:B11) -> 0.764 | F11: =F10+D11 -> 7.64 | G11: Athletics Over Individual
B12: 1 | C12: 2.85 | D12: =(B12*C12)-B12 -> 1.85 | E12: =SUM($D$2:D12)/SUM($B$2:B12) -> 0.86272727 | F12: =F11+D12 -> 9.49 | G12: Philadelphia Phillies Over Individual
A13: 45928 | B13: 1 | C13: 2.85 | D13: =(B13*C13)-B13 -> 1.85 | E13: =SUM($D$2:D13)/SUM($B$2:B13) -> 0.945 | F13: =F12+D13 -> 11.34 | G13: Houston Astros Over Individual
B15: =SUM(B2:B14) -> 12 | D15: =SUM(D2:D14) -> 11.34 | F15: =D15-MAX(F2:F14) -> 0 | H15: =D15-SUM(H2:H14) -> 11.34 | I15: =D15-SUM(I2:I14) -> 11.34 | J15: =D15-SUM(J2:J14) -> 11.34
A17: Picks | C17: Valida Cuotas | H17: =100 -> 100 | J17: Bankroll (100$) | K17: 80.89 | M17: Bankroll (100$)
A18: =COUNT(B2:B14) -> 12 | C18: =I18 -> 5 | D18: 1.32 | E18: =C18*D18-C18 -> 1.6 | G18: Stake Minimo | H18: =H21/100 -> 1 | I18: =H18*5 -> 5 | J18: Stake Maximo | K18: =K21/100 -> 0.9223 | L18: =K18*5 -> 4.6115 | M18: Stake Maximo
A19: Acierto | C19: =E19/(D18-1) -> 9.375 | E19: 3 | G19: Ganancia | H19: =SUM(H2:H14) -> 0 | J19: Retiro | K19: =D15 -> 11.34 | M19: Retiro
A20: =COUNT(C2:C14)/A18 -> 0.66666667 | D20: =1/A20 -> 1.5 | G20: Ganancia Neta | H20: =(H19-I19) -> 0 | K20: =(K19-L19) -> 11.34
A21: Yield | G21: Bankroll+Ganancia | H21: =H17+H20 -> 100 | J21: =130-H21 -> 30 | K21: =K17+K20 -> 92.23 | O21: 74.148
A22: =D15/B15 -> 0.945 | G22: ROI | H22: =(H21-H17)/H17 -> 0 | I22: =B15/H17 -> 0.12 | J22: Rollover | K22: =(K21-K17)/K17 -> 0.14019038 | L22: =B15/K17 -> 0.14834961 | M22: Rollover
D39: Beneficio Neto
A40: Semana | B40: Jugada | E40: Yield
D42: Beneficio Neto
B43: Apuesta | D43: =SUM(D2:D2) -> 2.04 | E43: Yield
B44: =SUM(B2:B2) -> 1 | D44: =SUM(#REF!) -> #REF! | E44: =D43/B44 -> 2.04 | AK44: 47
B45: =SUM(#REF!) -> #REF! | D45: =SUM(#REF!) -> #REF! | E45: =D44/B45 -> #REF!
B46: =SUM(#REF!) -> #REF! | D46: =SUM(#REF!) -> #REF! | E46: =D45/B46 -> #REF!
B47: =SUM(#REF!) -> #REF! | D47: =SUM(#REF!) -> #REF! | E47: =D46/B47 -> #REF!
B48: =SUM(#REF!) -> #REF! | D48: =SUM(#REF!) -> #REF! | E48: =D47/B48 -> #REF!
B49: =SUM(#REF!) -> #REF! | D49: =SUM(#REF!) -> #REF! | E49: =D48/B49 -> #REF!
B50: =SUM(#REF!) -> #REF! | D50: =SUM(#REF!) -> #REF! | E50: =D49/B50 -> #REF!
B51: =SUM(#REF!) -> #REF! | D51: =SUM(#REF!) -> #REF! | E51: =D50/B51 -> #REF!
B52: =SUM(#REF!) -> #REF! | D52: =SUM(#REF!) -> #REF! | E52: =D51/B52 -> #REF!
B53: =SUM(#REF!) -> #REF! | D53: =SUM(#REF!) -> #REF! | E53: =D52/B53 -> #REF!
B54: =SUM(#REF!) -> #REF! | D54: =SUM(#REF!) -> #REF! | E54: =D53/B54 -> #REF!
B55: =SUM(#REF!) -> #REF! | D55: =SUM(#REF!) -> #REF! | E55: =D54/B55 -> #REF!
B56: =SUM(#REF!) -> #REF! | D56: =SUM(#REF!) -> #REF! | E56: =D55/B56 -> #REF!
B57: =SUM(#REF!) -> #REF! | D57: =SUM(#REF!) -> #REF! | E57: =D56/B57 -> #REF!
A66: Semana 1 | B66: =SUM(B2:B4) -> 3 | D66: =SUM(D2:D4) -> 0.04 | E66: =D66/B66 -> 0.013333333 | G66: Un ROI objetivo del 5% mensual
A67: Semana 2 | B67: =SUM(B5:B14) -> 9 | D67: =SUM(D5:D14) -> 11.3 | E67: =D67/B67 -> 1.2555556
...

Sheet MLB ML Over Partidos
A1: Fecha | B1: Jugada | C1: Cuota | D1: Beneficio Neto | E1: Yield | F1: $ | G1: Jugada | H1: Diario | I1: Semanal | J1: Mensual | M1: K% = W - [ (1 - W) / R ]
A2: 45905 | B2: 1 | C2: 1.93 | D2: =(B2*C2)-B2 -> 0.93 | E2: =SUM($D$2:D2)/SUM($B$2:B2) -> 0.93 | F2: =D2 -> 0.93 | G2: Pittsburgh Pirates vs Milwaukee Brewers Over
B3: 1 | C3: 1.86 | D3: =(B3*C3)-B3 -> 0.86 | E3: =SUM($D$2:D3)/SUM($B$2:B3) -> 0.895 | F3: =F2+D3 -> 1.79 | G3: New York Yankees vs Toronto Blue Jays Over
B4: 1 | C4: 2.01 | D4: =(B4*C4)-B4 -> 1.01 | E4: =SUM($D$2:D4)/SUM($B$2:B4) -> 0.93333333 | F4: =F3+D4 -> 2.8 | G4: Atlanta Braves vs Seattle Mariners Over
B5: 1 | D5: =(B5*C5)-B5 -> -1 | E5: =SUM($D$2:D5)/SUM($B$2:B5) -> 0.45 | F5: =F4+D5 -> 1.8 | G5: Texas Rangers vs Houston Astros Over
A6: 45906 | B6: 1 | D6: =(B6*C6)-B6 -> -1 | E6: =SUM($D$2:D6)/SUM($B$2:B6) -> 0.16 | F6: =F5+D6 -> 0.8 | G6: New York Yankees vs Toronto Blue Jays Over
B7: 1 | D7: =(B7*C7)-B7 -> -1 | E7: =SUM($D$2:D7)/SUM($B$2:B7) -> -0.033333333 | F7: =F6+D7 -> -0.2 | G7: St. Louis Cardinals vs San Francisco Giants Over
B8: 1 | D8: =(B8*C8)-B8 -> -1 | E8: =SUM($D$2:D8)/SUM($B$2:B8) -> -0.17142857 | F8: =F7+D8 -> -1.2 | G8: Colorado Rockies vs San Diego Padres Over
B9: 1 | D9: =(B9*C9)-B9 -> -1 | E9: =SUM($D$2:D9)/SUM($B$2:B9) -> -0.275 | F9: =F8+D9 -> -2.2 | G9: Pittsburgh Pirates vs Milwaukee Brewers Over
B10: 1 | D10: =(B10*C10)-B10 -> -1 | E10: =SUM($D$2:D10)/SUM($B$2:B10) -> -0.35555556 | F10: =F9+D10 -> -3.2 | G10: Arizona Diamondbacks vs Boston Red Sox Over
B11: 1 | C11: 1.97 | D11: =(B11*C11)-B11 -> 0.97 | E11: =SUM($D$2:D11)/SUM($B$2:B11) -> -0.223 | F11: =F10+D11 -> -2.23 | G11: Kansas City Royals vs Minnesota Twins Over
A12: 45907 | B12: 1 | D12: =(B12*C12)-B12 -> -1 | E12: =SUM($D$2:D12)/SUM($B$2:B12) -> -0.29363636 | F12: =F11+D12 -> -3.23 | G12: Tampa Bay Rays vs Cleveland Guardians Over
B13: 1 | D13: =(B13*C13)-B13 -> -1 | E13: =SUM($D$2:D13)/SUM($B$2:B13) -> -0.3525 | F13: =F12+D13 -> -4.23 | G13: St. Louis Cardinals vs San Francisco Giants Over
B14: 1 | C14: 1.9 | D14: =(B14*C14)-B14 -> 0.9 | E14: =SUM($D$2:D14)/SUM($B$2:B14) -> -0.25615385 | F14: =F13+D14 -> -3.33 | G14: New York Yankees vs Toronto Blue Jays Over
B15: 1 | C15: 1.88 | D15: =(B15*C15)-B15 -> 0.88 | E15: =SUM($D$2:D15)/SUM($B$2:B15) -> -0.175 | F15: =F14+D15 -> -2.45 | G15: Miami Marlins vs Philadelphia Phillies Over
B16: 1 | D16: =(B16*C16)-B16 -> -1 | E16: =SUM($D$2:D16)/SUM($B$2:B16) -> -0.23 | F16: =F15+D16 -> -3.45 | G16: Arizona Diamondbacks vs Boston Red Sox Over
A17: 45908 | B17: 1 | D17: =(B17*C17)-B17 -> -1 | E17: =SUM($D$2:D17)/SUM($B$2:B17) -> -0.278125 | F17: =F16+D17 -> -4.45 | G17: San Francisco Giants vs Arizona Diamondbacks Over
B18: 1 | D18: =(B18*C18)-B18 -> -1 | E18: =SUM($D$2:D18)/SUM($B$2:B18) -> -0.32058824 | F18: =F17+D18 -> -5.45 | G18: Philadelphia Phillies vs New York Mets Over
B19: 1 | C19: 1.909 | D19: =(B19*C19)-B19 -> 0.909 | E19: =SUM($D$2:D19)/SUM($B$2:B19) -> -0.25227778 | F19: =F18+D19 -> -4.541 | G19: Atlanta Braves vs Chicago Cubs Over
B20: 1 | D20: =(B20*C20)-B20 -> -1 | E20: =SUM($D$2:D20)/SUM($B$2:B20) -> -0.29163158 | F20: =F19+D20 -> -5.541 | G20: Texas Rangers vs Milwaukee Brewers Over
A21: 45909 | B21: 1 | C21: 1.74 | D21: =(B21*C21)-B21 -> 0.74 | E21: =SUM($D$2:D21)/SUM($B$2:B21) -> -0.24005 | F21: =F20+D21 -> -4.801 | G21: Athletics vs Boston Red Sox Over
B22: 1 | C22: 1.89 | D22: =(B22*C22)-B22 -> 0.89 | E22: =SUM($D$2:D22)/SUM($B$2:B22) -> -0.1862381 | F22: =F21+D22 -> -3.911 | G22: Los Angeles Angels vs Minnesota Twins Over
B23: 1 | D23: =(B23*C23)-B23 -> -1 | E23: =SUM($D$2:D23)/SUM($B$2:B23) -> -0.22322727 | F23: =F22+D23 -> -4.911 | G23: Texas Rangers vs Milwaukee Brewers Over
A24: 45910 | B24: 1 | C24: 1.727 | D24: =(B24*C24)-B24 -> 0.727 | E24: =SUM($D$2:D24)/SUM($B$2:B24) -> -0.18191304 | F24: =F23+D24 -> -4.184 | G24: Athletics vs Boston Red Sox Over
B25: 1 | D25: =(B25*C25)-B25 -> -1 | E25: =SUM($D$2:D25)/SUM($B$2:B25) -> -0.216 | F25: =F24+D25 -> -5.184 | G25: Atlanta Braves vs Chicago Cubs Over
B26: 1 | D26: =(B26*C26)-B26 -> -1 | E26: =SUM($D$2:D26)/SUM($B$2:B26) -> -0.24736 | F26: =F25+D26 -> -6.184 | G26: Los Angeles Angels vs Minnesota Twins Over
A27: 45911 | B27: 1 | C27: 1.92 | D27: =(B27*C27)-B27 -> 0.92 | E27: =SUM($D$2:D27)/SUM($B$2:B27) -> -0.20246154 | F27: =F26+D27 -> -5.264 | G27: Toronto Blue Jays vs Houston Astros Over
B28: 1 | C28: 1.98 | D28: =(B28*C28)-B28 -> 0.98 | E28: =SUM($D$2:D28)/SUM($B$2:B28) -> -0.15866667 | F28: =F27+D28 -> -4.284 | G28: Miami Marlins vs Washington Nationals Over
A29: 45912 | B29: 1 | C29: 1.76 | D29: =(B29*C29)-B29 -> 0.76 | E29: =SUM($D$2:D29)/SUM($B$2:B29) -> -0.12585714 | F29: =F28+D29 -> -3.524 | G29: Athletics vs Cincinnati Reds Over
B30: 1 | D30: =(B30*C30)-B30 -> -1 | E30: =SUM($D$2:D30)/SUM($B$2:B30) -> -0.156 | F30: =F29+D30 -> -4.524 | G30: Atlanta Braves vs Houston Astros Over
B31: 1 | C31: 1.93 | D31: =(B31*C31)-B31 -> 0.93 | E31: =SUM($D$2:D31)/SUM($B$2:B31) -> -0.1198 | F31: =F30+D31 -> -3.594 | G31: Minnesota Twins vs Arizona Diamondbacks Over
B32: 1 | D32: =(B32*C32)-B32 -> -1 | E32: =SUM($D$2:D32)/SUM($B$2:B32) -> -0.14819355 | F32: =F31+D32 -> -4.594 | G32: Cleveland Guardians vs Chicago White Sox Over
B33: 1 | C33: 1.89 | D33: =(B33*C33)-B33 -> 0.89 | E33: =SUM($D$2:D33)/SUM($B$2:B33) -> -0.11575 | F33: =F32+D33 -> -3.704 | G33: Boston Red Sox vs New York Yankees Over
A34: 45913 | B34: 1 | C34: 1.89 | D34: =(B34*C34)-B34 -> 0.89 | E34: =SUM($D$2:D34)/SUM($B$2:B34) -> -0.085272727 | F34: =F33+D34 -> -2.814 | G34: Toronto Blue Jays vs Baltimore Orioles Over
B35: 1 | C35: 2.02 | D35: =(B35*C35)-B35 -> 1.02 | E35: =SUM($D$2:D35)/SUM($B$2:B35) -> -0.052764706 | F35: =F34+D35 -> -1.794 | G35: San Francisco Giants vs Los Angeles Dodgers Over
B36: 1 | C36: 1.92 | D36: =(B36*C36)-B36 -> 0.92 | E36: =SUM($D$2:D36)/SUM($B$2:B36) -> -0.024971429 | F36: =F35+D36 -> -0.874 | G36: Boston Red Sox vs New York Yankees Over
B37: 1 | D37: =(B37*C37)-B37 -> -1 | E37: =SUM($D$2:D37)/SUM($B$2:B37) -> -0.052055556 | F37: =F36+D37 -> -1.874 | G37: Athletics vs Cincinnati Reds Over
B38: 1 | D38: =(B38*C38)-B38 -> -1 | E38: =SUM($D$2:D38)/SUM($B$2:B38) -> -0.077675676 | F38: =F37+D38 -> -2.874 | G38: Chicago Cubs vs Tampa Bay Rays Over
B39: 1 | C39: 1.98 | D39: =(B39*C39)-B39 -> 0.98 | E39: =SUM($D$2:D39)/SUM($B$2:B39) -> -0.049842105 | F39: =F38+D39 -> -1.894 | G39: Milwaukee Brewers vs St. Louis Cardinals Over
B40: 1 | C40: 1.9 | D40: =(B40*C40)-B40 -> 0.9 | E40: =SUM($D$2:D40)/SUM($B$2:B40) -> -0.025487179 | F40: =F39+D40 -> -0.994 | G40: Miami Marlins vs Detroit Tigers Over
...

Sheet YRFI
B1: Peso | D1: Arizona | E1: Ponderado | G1: Cleveland | H1: Ponderado | M1: Criterio de Kelly | N1: Stake = (bp - q) / b, donde 'b' es la cuota decimal, 'p' es nuestra probabilidad estimada y 'q' es 1 - p. | T1: Bs | U1: $ | V1: Rub
A2: % temporada | B2: 0.6 | D2: =26/61 -> 0.42622951 | E2: =B2*D2 -> 0.2557377 | G2: =15/62 -> 0.24193548 | H2: =B2*G2 -> 0.14516129 | M2: b = cuota | N2: 2 | T2: 100 | U2: 2.51
A3: % últimos 15 juegos | B3: 0.4 | D3: =9/15 -> 0.6 | E3: =B3*D3 -> 0.24 | G3: =6/15 -> 0.4 | H3: =B3*G3 -> 0.16 | M3: p = probabilidad implicita | N3: 0.6 | T3: 12297.25 | U3: =T3*U2/T2 -> 308.66097 | V3: 25504.7
B4: =SUM(B2:B3) -> 1 | E4: =SUM(E2:E3) -> 0.4957377 | H4: =SUM(H2:H3) -> 0.30516129 | J4: =(1 - E8) * (1 - H8) -> 0.37045736 | K4: NO | M4: q= analisis estadistico | N4: =1-N3 -> 0.4
J5: =1 - J4 -> 0.62954264 | K5: SI | M5: Stake | N5: =(N2*N3-N4)/N2 -> 0.4
A6: % temporada + % últimos 15 juegos | B6: 0.7 | D6: =E4 -> 0.4957377 | E6: =B6*D6 -> 0.34701639 | G6: =H4 -> 0.30516129 | H6: =B6*G6 -> 0.2136129 | M6: (bp - q)/b | N6: =N5/10 -> 0.04
A7: % de carreras permitidas por el pitcher rival | B7: 0.3 | D7: =4/14 -> 0.28571429 | E7: =B7*D7 -> 0.085714286 | G7: =4/9 -> 0.44444444 | H7: =B7*G7 -> 0.13333333
B8: =SUM(B6:B7) -> 1 | E8: =SUM(E6:E7) -> 0.43273068 | H8: =SUM(H6:H7) -> 0.34694624
D10: =D1 -> Arizona | E10: Ponderado | G10: =G1 -> Cleveland | H10: Ponderado | J10: =(1 - E11) * (1 - H11) -> 0.760876 | K10: NO
E11: 0.147 | H11: 0.108 | J11: =1 - J10 -> 0.239124 | K11: SI
D13: 0.147
D14: 0.108
D15: 0.239124
D16: 0.760876
T42: 12.297,25 equivalian a 25.504,70 Rub

Sheet MMP
A1: Period | B1: Date of Period Start | C1: Date of End Period | D1: Bankroll required for Withdrawl | E1: Withdrawal | F1: Bankroll after Withdrawal | G1: Profit required for withdawal | H1: Days on the Period | I1: % Growth per day | J1: $ Profit per day | K1: UNITS required per day to win | L1: Stake per pick (1 UNIT) | M1: Profit to look for per serie | N1: Max allowed lost PICK per serie
A2: 1 | B2: =P7 -> 45951 | C2: =DATE(YEAR(B2),MONTH(B2)+$P$8-1,DAY(B2)) -> 45951 | E2: 0 | F2: =P6 -> 700 | G2: =+F2*$P$9 -> 210 | H2: =+B3-B2 -> 31 | I2: =+(G2/F2)/H2 -> 0.0096774194 | J2: =+F2*I2 -> 6.7741935 | K2: =+J2/L2 -> 0.96774194 | L2: =+F2*$P$11 -> 7 | M2: =+F2*$P$14 -> 7 | N2: =+M2*$P$15 -> 52.5 | O2: =SUM(E2:E3)+F3 -> 910 | P2: =SUM(E2:E13) -> 2556.674
A3: 2 | B3: =DATE(YEAR(B2),MONTH(B2)+$P$8,DAY(B2)) -> 45982 | C3: =DATE(YEAR(B3),MONTH(B3)+$P$8-1,DAY(B3)) -> 45982 | D3: =+F2+G2 -> 910 | E3: =+G2*$P$10 -> 105 | F3: =+F2+G2-E3 -> 805 | G3: =+F3*$P$9 -> 241.5 | H3: =+B4-B3 -> 30 | I3: =+(G3/F3)/H3 -> 0.01 | J3: =+F3*I3 -> 8.05 | K3: =+J3/L3 -> 1 | L3: =+F3*$P$11 -> 8.05 | M3: =+F3*$P$14 -> 8.05 | N3: =+M3*$P$15 -> 60.375
A4: 3 | B4: =DATE(YEAR(B3),MONTH(B3)+$P$8,DAY(B3)) -> 46012 | C4: =DATE(YEAR(B4),MONTH(B4)+$P$8-1,DAY(B4)) -> 46012 | D4: =+F3+G3 -> 1046.5 | E4: =+G3*$P$10 -> 120.75 | F4: =+F3+G3-E4 -> 925.75 | G4: =+F4*$P$9 -> 277.725 | H4: =+B5-B4 -> 31 | I4: =+(G4/F4)/H4 -> 0.0096774194 | J4: =+F4*I4 -> 8.958871 | K4: =+J4/L4 -> 0.96774194 | L4: =+F4*$P$11 -> 9.2575 | M4: =+F4*$P$14 -> 9.2575 | N4: =+M4*$P$15 -> 69.43125 | S4: =P6 -> 700 | U4: Bankroll (8000€)
A5: 4 | B5: =DATE(YEAR(B4),MONTH(B4)+$P$8,DAY(B4)) -> 46043 | C5: =DATE(YEAR(B5),MONTH(B5)+$P$8-1,DAY(B5)) -> 46043 | D5: =+F4+G4 -> 1203.475 | E5: =+G4*$P$10 -> 138.8625 | F5: =+F4+G4-E5 -> 1064.6125 | G5: =+F5*$P$9 -> 319.38375 | H5: =+B6-B5 -> 31 | I5: =+(G5/F5)/H5 -> 0.0096774194 | J5: =+F5*I5 -> 10.302702 | K5: =+J5/L5 -> 0.96774194 | L5: =+F5*$P$11 -> 10.646125 | M5: =+F5*$P$14 -> 10.646125 | N5: =+M5*$P$15 -> 79.845937 | O5: Selections | R5: Stake Minimo | S5: =L2 -> 7 | T5: =S5*10 -> 70 | U5: Stake Maximo
A6: 5 | B6: =DATE(YEAR(B5),MONTH(B5)+$P$8,DAY(B5)) -> 46074 | C6: =DATE(YEAR(B6),MONTH(B6)+$P$8-1,DAY(B6)) -> 46074 | D6: =+F5+G5 -> 1383.9962 | E6: =+G5*$P$10 -> 159.69187 | F6: =+F5+G5-E6 -> 1224.3044 | G6: =+F6*$P$9 -> 367.29131 | H6: =+B7-B6 -> 28 | I6: =+(G6/F6)/H6 -> 0.010714286 | J6: =+F6*I6 -> 13.117547 | K6: =+J6/L6 -> 1.0714286 | L6: =+F6*$P$11 -> 12.243044 | M6: =+F6*$P$14 -> 12.243044 | N6: =+M6*$P$15 -> 91.822828 | O6: Initial bankroll | P6: 700 | R6: Ganancia | S6: 0 | U6: Retiro
A7: 6 | B7: =DATE(YEAR(B6),MONTH(B6)+$P$8,DAY(B6)) -> 46102 | C7: =DATE(YEAR(B7),MONTH(B7)+$P$8-1,DAY(B7)) -> 46102 | D7: =+F6+G6 -> 1591.5957 | E7: =+G6*$P$10 -> 183.64566 | F7: =+F6+G6-E7 -> 1407.95 | G7: =+F7*$P$9 -> 422.38501 | H7: =+B8-B7 -> 31 | I7: =+(G7/F7)/H7 -> 0.0096774194 | J7: =+F7*I7 -> 13.625323 | K7: =+J7/L7 -> 0.96774194 | L7: =+F7*$P$11 -> 14.0795 | M7: =+F7*$P$14 -> 14.0795 | N7: =+M7*$P$15 -> 105.59625 | O7: Starting date | P7: 45951 | R7: Ganancia Neta | S7: =(S6-T6) -> 0
A8: 7 | B8: =DATE(YEAR(B7),MONTH(B7)+$P$8,DAY(B7)) -> 46133 | C8: =DATE(YEAR(B8),MONTH(B8)+$P$8-1,DAY(B8)) -> 46133 | D8: =+F7+G7 -> 1830.335 | E8: =+G7*$P$10 -> 211.1925 | F8: =+F7+G7-E8 -> 1619.1425 | G8: =+F8*$P$9 -> 485.74276 | H8: =+B9-B8 -> 30 | I8: =+(G8/F8)/H8 -> 0.01 | J8: =+F8*I8 -> 16.191425 | K8: =+J8/L8 -> 1 | L8: =+F8*$P$11 -> 16.191425 | M8: =+F8*$P$14 -> 16.191425 | N8: =+M8*$P$15 -> 121.43569 | O8: Months between withdrawals | P8: 1 | R8: Bankroll+Ganancia | S8: =S4+S7 -> 700
A9: 8 | B9: =DATE(YEAR(B8),MONTH(B8)+$P$8,DAY(B8)) -> 46163 | C9: =DATE(YEAR(B9),MONTH(B9)+$P$8-1,DAY(B9)) -> 46163 | D9: =+F8+G8 -> 2104.8853 | E9: =+G8*$P$10 -> 242.87138 | F9: =+F8+G8-E9 -> 1862.0139 | G9: =+F9*$P$9 -> 558.60417 | H9: =+B10-B9 -> 31 | I9: =+(G9/F9)/H9 -> 0.0096774194 | J9: =+F9*I9 -> 18.01949 | K9: =+J9/L9 -> 0.96774194 | L9: =+F9*$P$11 -> 18.620139 | M9: =+F9*$P$14 -> 18.620139 | N9: =+M9*$P$15 -> 139.65104 | O9: % Increase Bankroll required for withdrawal | P9: 0.3
